<?xml version="1.0"?>
<sdf version="1.6">
	<model name='vehicle1'>

		<plugin filename="ignition-gazebo-diff-drive-system" name="ignition::gazebo::systems::DiffDrive">
			<left_joint>left_wheel_joint</left_joint>
			<right_joint>right_wheel_joint</right_joint>
			<wheel_separation>0.353</wheel_separation>
			<wheel_radius>0.074</wheel_radius>
			<odom_publish_frequency>20</odom_publish_frequency>
			<topic>/vehicle1/cmd_vel</topic>
			<odom_topic>/vehicle1/odom</odom_topic>
			<tf_topic>/vehicle1/tf</tf_topic>
			<frame_id>odom</frame_id>
			<child_frame_id>base_footprint</child_frame_id>
			<max_linear_acceleration>5</max_linear_acceleration>
			<min_linear_acceleration>-5</min_linear_acceleration>
			<max_angular_acceleration>25</max_angular_acceleration>
			<min_angular_acceleration>-25</min_angular_acceleration>
			<!--max_linear_velocity>0.5</max_linear_velocity-->
			<!--min_linear_velocity>-0.5</min_linear_velocity-->
			<!--max_angular_velocity>1</max_angular_velocity-->
			<!--min_angular_velocity>-1</min_angular_velocity-->
		</plugin>

		<link name='base_footprint'></link>

		<joint name='base_joint' type='fixed'>
			<parent>base_footprint</parent>
			<child>base_link</child>
		</joint>

		<link name='base_link'>
			<pose>0 0 0 0 0 0</pose>
			<inertial>
				<pose>-0.086 0 0.146 0 0 0</pose>
				<mass>10</mass>
				<inertia>
					<ixx>0.0667</ixx>
					<ixy>0</ixy>
					<ixz>0</ixz>
					<iyy>0.177</iyy>
					<iyz>0</iyz>
					<izz>0.200</izz>
				</inertia>
			</inertial>
			<visual name='visual1'>
				<pose>-0.086 0 0.146 0 0 0</pose>
				<geometry>
					<box>
						<size>0.432 0.232 0.162</size>
					</box>
				</geometry>
				<material>
					<ambient>1 0 0 0.8</ambient>
					<diffuse>1 0 0 0.8</diffuse>
					<specular>1 0 0 0.8</specular>
				</material>
			</visual>
			<collision name='collision1'>
				<pose>-0.086 0 0.146 0 0 0</pose>
				<geometry>
					<box>
						<size>0.432 0.232 0.162</size>
					</box>
				</geometry>
			</collision>
			<visual name='visual2'>
				<pose>-0.222 0 0.25 0 0 0</pose>
				<geometry>
					<box>
						<size>0.16 0.232 0.1</size>
					</box>
				</geometry>
				<material>
					<ambient>1 0 0 0.8</ambient>
					<diffuse>1 0 0 0.8</diffuse>
					<specular>1 0 0 0.8</specular>
				</material>
			</visual>
			<collision name='collision1\2'>
				<pose>-0.222 0 0.25 0 0 0</pose>
				<geometry>
					<box>
						<size>0.16 0.232 0.1</size>
					</box>
				</geometry>
			</collision>
		</link>

		<joint name='left_wheel_joint' type='revolute'>
			<parent>base_link</parent>
			<child>left_wheel</child>
			<axis>
				<xyz>0 0 1</xyz>
				<limit>
					<lower>-1.79769e+308</lower>
					<upper>1.79769e+308</upper>
				</limit>
			</axis>
		</joint>

		<link name='left_wheel'>
			<pose>0.0 0.1765 0.074 -1.5707 0 0</pose>
			<inertial>
				<mass>1</mass>
				<inertia>
					<ixx>0.00147</ixx>
					<ixy>0</ixy>
					<ixz>0</ixz>
					<iyy>0.00147</iyy>
					<iyz>0</iyz>
					<izz>0.00274</izz>
				</inertia>
			</inertial>
			<visual name='visual'>
				<geometry>
					<cylinder>
						<radius>0.074</radius>
						<length>0.035</length>
					</cylinder>
				</geometry>
				<material>
					<ambient>0 0 1 1</ambient>
					<diffuse>0 0 1 1</diffuse>
					<specular>0 0 1 1</specular>
				</material>
			</visual>
			<collision name='collision'>
				<geometry>
					<cylinder>
						<radius>0.074</radius>
						<length>0.035</length>
					</cylinder>
				</geometry>
				<surface>
					<friction>
						<ode>
							<mu>1.0</mu>
							<mu2>1.0</mu2>
						</ode>
					</friction>
				</surface>
			</collision>
		</link>

		<joint name='right_wheel_joint' type='revolute'>
			<parent>base_link</parent>
			<child>right_wheel</child>
			<axis>
				<xyz>0 0 1</xyz>
				<limit>
					<lower>-1.79769e+308</lower>
					<upper>1.79769e+308</upper>
				</limit>
			</axis>
		</joint>

		<link name='right_wheel'>
			<pose>0.0 -0.1765 0.074 -1.5707 0 0</pose>
			<inertial>
				<mass>1</mass>
				<inertia>
					<ixx>0.00147</ixx>
					<ixy>0</ixy>
					<ixz>0</ixz>
					<iyy>0.00147</iyy>
					<iyz>0</iyz>
					<izz>0.00274</izz>
				</inertia>
			</inertial>
			<visual name='visual'>
				<geometry>
					<cylinder>
						<radius>0.074</radius>
						<length>0.035</length>
					</cylinder>
				</geometry>
				<material>
					<ambient>0 0 1 1</ambient>
					<diffuse>0 0 1 1</diffuse>
					<specular>0 0 1 1</specular>
				</material>
			</visual>
			<collision name='collision'>
				<geometry>
					<cylinder>
						<radius>0.074</radius>
						<length>0.035</length>
					</cylinder>
				</geometry>
				<surface>
					<friction>
						<ode>
							<mu>1.0</mu>
							<mu2>1.0</mu2>
						</ode>
					</friction>
				</surface>
			</collision>
		</link>

		<joint name='caster_joint' type='universal'>
			<parent>base_link</parent>
			<child>caster</child>
		</joint>

		<link name='caster'>
			<pose>-0.25 0 0.03 0 0 0</pose>
			<inertial>
				<mass>0.1</mass>
				<inertia>
					<ixx>0.000018</ixx>
					<ixy>0</ixy>
					<ixz>0</ixz>
					<iyy>0.000018</iyy>
					<iyz>0</iyz>
					<izz>0.000018</izz>
				</inertia>
			</inertial>
			<visual name='visual'>
				<geometry>
					<sphere>
						<radius>0.03</radius>
					</sphere>
				</geometry>
				<material>
					<ambient>0.2 0.2 0.2 1</ambient>
					<diffuse>0.2 0.2 0.2 1</diffuse>
					<specular>0.2 0.2 0.2 1</specular>
				</material>
			</visual>
			<collision name='collision'>
				<geometry>
					<sphere>
						<radius>0.03</radius>
					</sphere>
				</geometry>
				<surface>
					<friction>
						<ode>
							<mu>0</mu>
							<mu2>0</mu2>
						</ode>
					</friction>
				</surface>
			</collision>
		</link>

		<joint name='lidar_joint' type='fixed'>
			<parent>base_link</parent>
			<child>base_scan</child>
		</joint>

		<link name="base_scan">
			<pose>0.07 0 0.285 0 0 0</pose>
			<inertial>
				<mass>0.2</mass>
				<inertia>
					<ixx>0.0000833</ixx>
					<iyy>0.0000833</iyy>
					<izz>0.0000833</izz>
				</inertia>
			</inertial>
			<visual name="visual">
				<geometry>
					<box>
						<size>0.05 0.05 0.05</size>
					</box>
				</geometry>
				<material>
					<ambient>1 0 0 1</ambient>
					<diffuse>1 0 0 1</diffuse>
					<specular>1 0 0 1</specular>
				</material>
			</visual>
			<collision name="collision">
				<geometry>
					<box>
						<size>0.05 0.05 0.05</size>
					</box>
				</geometry>
			</collision>
			<sensor name="gpu_lidar" type="gpu_lidar">
				<topic>/vehicle1/scan</topic>
				<ignition_frame_id>base_scan</ignition_frame_id>
				<update_rate>10</update_rate>
				<lidar>
					<scan>
						<horizontal>
							<samples>640</samples>
							<resolution>1</resolution>
							<min_angle>-2.35619</min_angle>
							<max_angle>2.35619</max_angle>
						</horizontal>
						<!--vertical>
							<samples>2</samples>
						</vertical-->
					</scan>
					<range>
						<min>0.1</min>
						<max>30.0</max>
						<resolution>0.0043</resolution>
					</range>
					<noise>
						<type>gaussian</type>
						<mean>0.0</mean>
						<stddev>0.01</stddev>
					</noise>
				</lidar>
				<alwaysOn>1</alwaysOn>
				<visualize>true</visualize>
			</sensor>
		</link>

		<joint name='camera_joint' type='fixed'>
			<parent>base_link</parent>
			<child>base_camera</child>
		</joint>

		<link name="base_camera">
			<pose>0.07 0 0.35 0 0 0</pose>
			<inertial>
				<mass>0.1</mass>
				<inertia>
					<ixx>0.0000267</ixx>
					<iyy>0.0000267</iyy>
					<izz>0.0000267</izz>
				</inertia>
			</inertial>
			<visual name="visual">
				<geometry>
					<box>
						<size>0.04 0.04 0.04</size>
					</box>
				</geometry>
				<material>
					<ambient>0 1 0 1</ambient>
					<diffuse>0 1 0 1</diffuse>
					<specular>0 1 0 1</specular>
				</material>
			</visual>
			<collision name="collision">
				<geometry>
					<box>
						<size>0.04 0.04 0.04</size>
					</box>
				</geometry>
			</collision>
			<sensor name="camera" type="camera">
				<camera>
					<horizontal_fov>2.047</horizontal_fov>
					<image>
						<width>320</width>
						<height>240</height>
					</image>
					<clip>
						<near>0.1</near>
						<far>100</far>
					</clip>
				</camera>
				<always_on>1</always_on>
				<update_rate>30</update_rate>
				<visualize>true</visualize>
				<topic>/vehicle1/image_raw</topic>
			</sensor>
		</link>

		<!--joint name='left_wheel_dummy_joint' type='fixed'>
			<parent>base_link</parent>
			<child>left_dummy_wheel</child>
		</joint>

		<link name='left_dummy_wheel'>
			<pose>0 0.1765 0.074 -1.5707 0 0</pose>
			<inertial>
				<mass>0.0</mass>
				<inertia>
					<ixx>0.0</ixx>
					<iyy>0.0</iyy>
					<izz>0.0</izz>
				</inertia>
			</inertial>
		</link>

		<joint name='right_wheel_dummy_joint' type='fixed'>
			<parent>base_link</parent>
			<child>right_dummy_wheel</child>
		</joint>

		<link name='right_dummy_wheel'>
			<pose>0 -0.1765 0.074 -1.5707 0 0</pose>
			<inertial>
				<mass>0.0</mass>
				<inertia>
					<ixx>0.0</ixx>
					<iyy>0.0</iyy>
					<izz>0.0</izz>
				</inertia>
			</inertial>
		</link>

		<joint name='caster_dummy_joint' type='fixed'>
			<parent>base_link</parent>
			<child>caster_dummy</child>
		</joint>

		<link name='caster_dummy'>
			<pose>-0.25 0 0.03 0 0 0</pose>
			<inertial>
				<mass>0.0</mass>
				<inertia>
					<ixx>0.0</ixx>
					<iyy>0.0</iyy>
					<izz>0.0</izz>
				</inertia>
			</inertial>
		</link-->

	</model>

</sdf>
